<?xml version='1.0'?>
<sdf version='1.6'>
  <model name='movo'>
    <link name='base_link'>
      <pose frame=''>0 0 0 0 -0 0</pose>
      <inertial>
        <pose frame=''>-0.002974 -0.008419 0.237851 0 -0 0</pose>
        <mass>67.9184</mass>
        <inertia>
          <ixx>3.97207</ixx>
          <ixy>-0.00341811</ixy>
          <ixz>-0.0764064</ixz>
          <iyy>4.23328</iyy>
          <iyz>-0.075981</iyz>
          <izz>0.697625</izz>
        </inertia>
      </inertial>
      <collision name='base_link_fixed_joint_lump__base_chassis_link_collision'>
        <pose frame=''>0 0 0.0762 0 -0 0</pose>
        <geometry>
          <mesh>
            <scale>1 1 1</scale>
            <uri>file://movo/meshes/movo_components/collision/vector_base_collision.stl</uri>
          </mesh>
        </geometry>
      </collision>
      <collision name='base_link_fixed_joint_lump__linear_actuator_fixed_link_collision_1'>
        <pose frame=''>0 0 0.0762 0 -0 0</pose>
        <geometry>
          <mesh>
            <scale>1 1 1</scale>
            <uri>file://movo/meshes/movo_components/collision/movo_fixed_body_collision.stl</uri>
          </mesh>
        </geometry>
      </collision>
      <visual name='base_link_fixed_joint_lump__base_chassis_link_visual'>
        <pose frame=''>0 0 0.0762 0 -0 0</pose>
        <geometry>
          <mesh>
            <scale>1 1 1</scale>
            <uri>file://movo/meshes/movo_components/visual/vector_base.dae</uri>
          </mesh>
        </geometry>
      </visual>
      <visual name='base_link_fixed_joint_lump__linear_actuator_fixed_link_visual_1'>
        <pose frame=''>0 0 0.0762 0 -0 0</pose>
        <geometry>
          <mesh>
            <scale>1 1 1</scale>
            <uri>file://movo/meshes/movo_components/visual/movo_fixed_payload.dae</uri>
          </mesh>
        </geometry>
      </visual>
      <visual name='base_link_fixed_joint_lump__lower_body_link_visual_2'>
        <pose frame=''>0 0 0.0762 0 -0 0</pose>
        <geometry>
          <mesh>
            <scale>1 1 1</scale>
            <uri>file://movo/meshes/movo_body/movo_lower_body.dae</uri>
          </mesh>
        </geometry>
      </visual>
    </link>
    <link name='linear_actuator_link'>
      <pose frame=''>0.07714 0 0.470076 0 -0 0</pose>
      <inertial>
        <pose frame=''>-0.06514 -0.002828 0.356497 0 -0 0</pose>
        <mass>20.7437</mass>
        <inertia>
          <ixx>0.8115</ixx>
          <ixy>-0.0106441</ixy>
          <ixz>-0.0608701</ixz>
          <iyy>0.839619</iyy>
          <iyz>-0.022887</iyz>
          <izz>0.666234</izz>
        </inertia>
      </inertial>
      <collision name='linear_actuator_link_collision'>
        <pose frame=''>0 0 0 0 -0 0</pose>
        <geometry>
          <mesh>
            <scale>1 1 1</scale>
            <uri>file://movo/meshes/movo_components/collision/movo_upper_body_collision.stl</uri>
          </mesh>
        </geometry>
      </collision>
      <collision name='linear_actuator_link_fixed_joint_lump__left_base_link_collision_1'>
        <pose frame=''>0.026105 0.13335 0.279994 -1.5708 -0 -1.5708</pose>
        <geometry>
          <mesh>
            <scale>1 1 1</scale>
            <uri>file://movo/meshes/manipulation/jaco/collision/base.stl</uri>
          </mesh>
        </geometry>
      </collision>
      <collision name='linear_actuator_link_fixed_joint_lump__pan_base_link_collision_2'>
        <pose frame=''>0.19735 0 0.344989 0 -0 0</pose>
        <geometry>
          <mesh>
            <scale>1 1 1</scale>
            <uri>file://movo/meshes/pan_tilt/collision/pan_tilt_base.stl</uri>
          </mesh>
        </geometry>
      </collision>
      <collision name='linear_actuator_link_fixed_joint_lump__right_base_link_collision_3'>
        <pose frame=''>0.026105 -0.13335 0.279994 -1.5708 -0 -1.5708</pose>
        <geometry>
          <mesh>
            <scale>1 1 1</scale>
            <uri>file://movo/meshes/manipulation/jaco/collision/base.stl</uri>
          </mesh>
        </geometry>
      </collision>
      <visual name='linear_actuator_link_visual'>
        <pose frame=''>0 0 0 0 -0 0</pose>
        <geometry>
          <mesh>
            <scale>1 1 1</scale>
            <uri>file://movo/meshes/movo_components/visual/movo_moving_payload.dae</uri>
          </mesh>
        </geometry>
      </visual>
      <visual name='linear_actuator_link_fixed_joint_lump__left_base_link_visual_1'>
        <pose frame=''>0.026105 0.13335 0.279994 -1.5708 -0 -1.5708</pose>
        <geometry>
          <mesh>
            <scale>1 1 1</scale>
            <uri>file://movo/meshes/manipulation/jaco/visual/base.dae</uri>
          </mesh>
        </geometry>
      </visual>
      <visual name='linear_actuator_link_fixed_joint_lump__pan_base_link_visual_2'>
        <pose frame=''>0.19735 0 0.344989 0 -0 0</pose>
        <geometry>
          <mesh>
            <scale>1 1 1</scale>
            <uri>file://movo/meshes/pan_tilt/visual/pan_tilt_base.dae</uri>
          </mesh>
        </geometry>
      </visual>
      <visual name='linear_actuator_link_fixed_joint_lump__right_base_link_visual_3'>
        <pose frame=''>0.026105 -0.13335 0.279994 -1.5708 -0 -1.5708</pose>
        <geometry>
          <mesh>
            <scale>1 1 1</scale>
            <uri>file://movo/meshes/manipulation/jaco/visual/base.dae</uri>
          </mesh>
        </geometry>
      </visual>
      <visual name='linear_actuator_link_fixed_joint_lump__upper_body_link_visual_4'>
        <pose frame=''>0 0 0 0 -0 0</pose>
        <geometry>
          <mesh>
            <scale>1 1 1</scale>
            <uri>file://movo/meshes/movo_body/movo_upper_body.dae</uri>
          </mesh>
        </geometry>
      </visual>
    </link>
    <joint name='linear_joint' type='prismatic'>
      <child>linear_actuator_link</child>
      <parent>base_link</parent>
      <axis>
        <xyz>0 0 1</xyz>
        <limit>
          <lower>0</lower>
          <upper>0.472</upper>
          <effort>1000</effort>
          <velocity>0.2</velocity>
        </limit>
        <dynamics>
          <damping>0</damping>
          <friction>0</friction>
          <spring_reference>0</spring_reference>
          <spring_stiffness>0</spring_stiffness>
        </dynamics>
        <use_parent_model_frame>1</use_parent_model_frame>
      </axis>
    </joint>
    <link name='left_shoulder_link'>
      <pose frame=''>0.165745 0.13335 0.75007 -1.5708 0 1.5708</pose>
      <inertial>
        <pose frame=''>1.8e-05 -0.004667 -0.060609 0 -0 0</pose>
        <mass>0.824524</mass>
        <inertia>
          <ixx>0.002561</ixx>
          <ixy>0</ixy>
          <ixz>1e-06</ixz>
          <iyy>0.002653</iyy>
          <iyz>0.000212</iyz>
          <izz>0.000524</izz>
        </inertia>
      </inertial>
      <collision name='left_shoulder_link_collision'>
        <pose frame=''>0 0 0 0 -0 0</pose>
        <geometry>
          <mesh>
            <scale>1 1 1</scale>
            <uri>file://movo/meshes/manipulation/jaco/collision/shoulder_7dof.stl</uri>
          </mesh>
        </geometry>
      </collision>
      <visual name='left_shoulder_link_visual'>
        <pose frame=''>0 0 0 0 -0 0</pose>
        <geometry>
          <mesh>
            <scale>1 1 1</scale>
            <uri>file://movo/meshes/manipulation/jaco/visual/shoulder_7dof.dae</uri>
          </mesh>
        </geometry>
      </visual>
    </link>
    <joint name='left_shoulder_pan_joint' type='revolute'>
      <child>left_shoulder_link</child>
      <parent>linear_actuator_link</parent>
      <axis>
        <xyz>-1 -0 -0</xyz>
        <limit>
          <lower>-3.14159</lower>
          <upper>3.14159</upper>
          <effort>18000</effort>
          <velocity>0.69115</velocity>
        </limit>
        <dynamics>
          <damping>0.01</damping>
          <friction>0</friction>
          <spring_reference>0</spring_reference>
          <spring_stiffness>0</spring_stiffness>
        </dynamics>
        <use_parent_model_frame>1</use_parent_model_frame>
      </axis>
    </joint>
    <link name='left_arm_half_1_link'>
      <pose frame=''>0.284495 0.13335 0.75007 -0 0 1.5708</pose>
      <inertial>
        <pose frame=''>0 -0.103563 0 0 -0 0</pose>
        <mass>0.8447</mass>
        <inertia>
          <ixx>0.000435</ixx>
          <ixy>2e-06</ixy>
          <ixz>0.000231</ixz>
          <iyy>0.034947</iyy>
          <iyz>0</iyz>
          <izz>0.035198</izz>
        </inertia>
      </inertial>
      <collision name='left_arm_half_1_link_collision'>
        <pose frame=''>0 0 0 0 -0 0</pose>
        <geometry>
          <mesh>
            <scale>1 1 1</scale>
            <uri>file://movo/meshes/manipulation/jaco/collision/arm_half_1.stl</uri>
          </mesh>
        </geometry>
      </collision>
      <visual name='left_arm_half_1_link_visual'>
        <pose frame=''>0 0 0 0 -0 0</pose>
        <geometry>
          <mesh>
            <scale>1 1 1</scale>
            <uri>file://movo/meshes/manipulation/jaco/visual/arm_half_1.dae</uri>
          </mesh>
        </geometry>
      </visual>
    </link>
    <joint name='left_shoulder_lift_joint' type='revolute'>
      <child>left_arm_half_1_link</child>
      <parent>left_shoulder_link</parent>
      <axis>
        <xyz>-0 0 1</xyz>
        <limit>
          <lower>-2.238</lower>
          <upper>2.238</upper>
          <effort>30000.5</effort>
          <velocity>0.69115</velocity>
        </limit>
        <dynamics>
          <damping>0.01</damping>
          <friction>0</friction>
          <spring_reference>0</spring_reference>
          <spring_stiffness>0</spring_stiffness>
        </dynamics>
        <use_parent_model_frame>1</use_parent_model_frame>
      </axis>
    </joint>
    <link name='left_arm_half_2_link'>
      <pose frame=''>0.489495 0.13335 0.75007 -1.5708 0 1.5708</pose>
      <inertial>
        <pose frame=''>0 0 -0.102245 0 -0 0</pose>
        <mass>0.8447</mass>
        <inertia>
          <ixx>0.000435</ixx>
          <ixy>2e-06</ixy>
          <ixz>0.000231</ixz>
          <iyy>0.034947</iyy>
          <iyz>0</iyz>
          <izz>0.035198</izz>
        </inertia>
      </inertial>
      <collision name='left_arm_half_2_link_collision'>
        <pose frame=''>0 0 0 0 -0 0</pose>
        <geometry>
          <mesh>
            <scale>1 1 1</scale>
            <uri>file://movo/meshes/manipulation/jaco/collision/arm_half_2.stl</uri>
          </mesh>
        </geometry>
      </collision>
      <visual name='left_arm_half_2_link_visual'>
        <pose frame=''>0 0 0 0 -0 0</pose>
        <geometry>
          <mesh>
            <scale>1 1 1</scale>
            <uri>file://movo/meshes/manipulation/jaco/visual/arm_half_2.dae</uri>
          </mesh>
        </geometry>
      </visual>
    </link>
    <joint name='left_arm_half_joint' type='revolute'>
      <child>left_arm_half_2_link</child>
      <parent>left_arm_half_1_link</parent>
      <axis>
        <xyz>-1 -0 -0</xyz>
        <limit>
          <lower>-3.14159</lower>
          <upper>3.14159</upper>
          <effort>30000.5</effort>
          <velocity>0.69115</velocity>
        </limit>
        <dynamics>
          <damping>0.01</damping>
          <friction>0</friction>
          <spring_reference>0</spring_reference>
          <spring_stiffness>0</spring_stiffness>
        </dynamics>
        <use_parent_model_frame>1</use_parent_model_frame>
      </axis>
    </joint>
    <link name='left_forearm_link'>
      <pose frame=''>0.694495 0.13335 0.75007 -3.14159 0 1.5708</pose>
      <inertial>
        <pose frame=''>0 0.081 -0.0086 0 -0 0</pose>
        <mass>0.674254</mass>
        <inertia>
          <ixx>0.005453</ixx>
          <ixy>3e-06</ixy>
          <ixz>0</ixz>
          <iyy>0.000305</iyy>
          <iyz>8.7e-05</iyz>
          <izz>0.005578</izz>
        </inertia>
      </inertial>
      <collision name='left_forearm_link_collision'>
        <pose frame=''>0 0 0 0 -0 0</pose>
        <geometry>
          <mesh>
            <scale>1 1 1</scale>
            <uri>file://movo/meshes/manipulation/jaco/collision/forearm_7dof.stl</uri>
          </mesh>
        </geometry>
      </collision>
      <visual name='left_forearm_link_visual'>
        <pose frame=''>0 0 0 0 -0 0</pose>
        <geometry>
          <mesh>
            <scale>1 1 1</scale>
            <uri>file://movo/meshes/manipulation/jaco/visual/forearm_7dof.dae</uri>
          </mesh>
        </geometry>
      </visual>
    </link>
    <joint name='left_elbow_joint' type='revolute'>
      <child>left_forearm_link</child>
      <parent>left_arm_half_2_link</parent>
      <axis>
        <xyz>-0 -0 -1</xyz>
        <limit>
          <lower>-2.809</lower>
          <upper>2.809</upper>
          <effort>18000</effort>
          <velocity>0.69115</velocity>
        </limit>
        <dynamics>
          <damping>0.01</damping>
          <friction>0</friction>
          <spring_reference>0</spring_reference>
          <spring_stiffness>0</spring_stiffness>
        </dynamics>
        <use_parent_model_frame>1</use_parent_model_frame>
      </axis>
    </joint>
    <link name='left_wrist_spherical_1_link'>
      <pose frame=''>0.901795 0.13335 0.76147 1.5708 -0 -1.5708</pose>
      <inertial>
        <pose frame=''>0 0.002885 -0.054193 0 -0 0</pose>
        <mass>0.463</mass>
        <inertia>
          <ixx>0.000392</ixx>
          <ixy>0</ixy>
          <ixz>0</ixz>
          <iyy>0.000347</iyy>
          <iyz>0.000101</iyz>
          <izz>0.000233</izz>
        </inertia>
      </inertial>
      <collision name='left_wrist_spherical_1_link_collision'>
        <pose frame=''>0 0 0 0 -0 0</pose>
        <geometry>
          <mesh>
            <scale>1 1 1</scale>
            <uri>file://movo/meshes/manipulation/jaco/collision/wrist_spherical_1.stl</uri>
          </mesh>
        </geometry>
      </collision>
      <visual name='left_wrist_spherical_1_link_visual'>
        <pose frame=''>0 0 0 0 -0 0</pose>
        <geometry>
          <mesh>
            <scale>1 1 1</scale>
            <uri>file://movo/meshes/manipulation/jaco/visual/wrist_spherical_1.dae</uri>
          </mesh>
        </geometry>
      </visual>
    </link>
    <joint name='left_wrist_spherical_1_joint' type='revolute'>
      <child>left_wrist_spherical_1_link</child>
      <parent>left_forearm_link</parent>
      <axis>
        <xyz>-1 -0 0</xyz>
        <limit>
          <lower>-3.14159</lower>
          <upper>3.14159</upper>
          <effort>60000.8</effort>
          <velocity>0.921534</velocity>
        </limit>
        <dynamics>
          <damping>0.01</damping>
          <friction>0</friction>
          <spring_reference>0</spring_reference>
          <spring_stiffness>0</spring_stiffness>
        </dynamics>
        <use_parent_model_frame>1</use_parent_model_frame>
      </axis>
    </joint>
    <link name='left_wrist_spherical_2_link'>
      <pose frame=''>1.00554 0.13335 0.76147 -0 -0 -1.5708</pose>
      <inertial>
        <pose frame=''>0 0.049721 -0.002856 0 -0 0</pose>
        <mass>0.463</mass>
        <inertia>
          <ixx>0.000392</ixx>
          <ixy>0</ixy>
          <ixz>0</ixz>
          <iyy>0.000347</iyy>
          <iyz>0.000101</iyz>
          <izz>0.000233</izz>
        </inertia>
      </inertial>
      <collision name='left_wrist_spherical_2_link_collision'>
        <pose frame=''>0 0 0 0 -0 0</pose>
        <geometry>
          <mesh>
            <scale>1 1 1</scale>
            <uri>file://movo/meshes/manipulation/jaco/collision/wrist_spherical_2.stl</uri>
          </mesh>
        </geometry>
      </collision>
      <visual name='left_wrist_spherical_2_link_visual'>
        <pose frame=''>0 0 0 0 -0 0</pose>
        <geometry>
          <mesh>
            <scale>1 1 1</scale>
            <uri>file://movo/meshes/manipulation/jaco/visual/wrist_spherical_2.dae</uri>
          </mesh>
        </geometry>
      </visual>
    </link>
    <joint name='left_wrist_spherical_2_joint' type='revolute'>
      <child>left_wrist_spherical_2_link</child>
      <parent>left_wrist_spherical_1_link</parent>
      <axis>
        <xyz>0 0 1</xyz>
        <limit>
          <lower>-2.78</lower>
          <upper>2.78</upper>
          <effort>60000.8</effort>
          <velocity>0.921534</velocity>
        </limit>
        <dynamics>
          <damping>0.01</damping>
          <friction>0</friction>
          <spring_reference>0</spring_reference>
          <spring_stiffness>0</spring_stiffness>
        </dynamics>
        <use_parent_model_frame>1</use_parent_model_frame>
      </axis>
    </joint>
    <link name='left_wrist_3_link'>
      <pose frame=''>1.10929 0.13335 0.76147 -1.5708 0 1.5708</pose>
      <inertial>
        <pose frame=''>0.029969 5e-06 -0.100001 0 -0 0</pose>
        <mass>1.78941</mass>
        <inertia>
          <ixx>0.00515211</ixx>
          <ixy>-0.000274989</ixy>
          <ixz>0.000258842</ixz>
          <iyy>0.00680845</iyy>
          <iyz>0.000160119</iyz>
          <izz>0.00373896</izz>
        </inertia>
      </inertial>
      <collision name='left_wrist_3_link_collision'>
        <pose frame=''>0 0 0 0 -0 0</pose>
        <geometry>
          <mesh>
            <scale>1 1 1</scale>
            <uri>file://movo/meshes/manipulation/jaco/collision/kinova_actuator_gearing.stl</uri>
          </mesh>
        </geometry>
      </collision>
      <collision name='left_wrist_3_link_fixed_joint_lump__left_ee_link_collision_1'>
        <pose frame=''>0 0 -0.105 3.14159 1.57079 3e-06</pose>
        <geometry>
          <sphere>
            <radius>0.01</radius>
          </sphere>
        </geometry>
      </collision>
      <collision name='left_wrist_3_link_fixed_joint_lump__left_gripper_base_link_collision_2'>
        <pose frame=''>-0 0 0 0 -0 0</pose>
        <geometry>
          <mesh>
            <scale>1 1 1</scale>
            <uri>file://movo/meshes/manipulation/kinova_grippers/collision/kg3_base_link.stl</uri>
          </mesh>
        </geometry>
      </collision>
      <visual name='left_wrist_3_link_visual'>
        <pose frame=''>0 0 0 0 -0 0</pose>
        <geometry>
          <mesh>
            <scale>1 1 1</scale>
            <uri>file://movo/meshes/manipulation/jaco/visual/kinova_actuator_gearing.dae</uri>
          </mesh>
        </geometry>
      </visual>
      <visual name='left_wrist_3_link_fixed_joint_lump__left_ee_link_visual_1'>
        <pose frame=''>0 0 -0.105 3.14159 1.57079 3e-06</pose>
        <geometry>
          <sphere>
            <radius>0.01</radius>
          </sphere>
        </geometry>
      </visual>
      <visual name='left_wrist_3_link_fixed_joint_lump__left_gripper_base_link_visual_2'>
        <pose frame=''>-0 0 0 0 -0 0</pose>
        <geometry>
          <mesh>
            <scale>1 1 1</scale>
            <uri>file://movo/meshes/manipulation/kinova_grippers/visual/kg3_base_link.dae</uri>
          </mesh>
        </geometry>
      </visual>
    </link>
    <joint name='left_wrist_3_joint' type='revolute'>
      <child>left_wrist_3_link</child>
      <parent>left_wrist_spherical_2_link</parent>
      <axis>
        <xyz>-1 -0 -0</xyz>
        <limit>
          <lower>-3.14159</lower>
          <upper>3.14159</upper>
          <effort>60000.8</effort>
          <velocity>0.921534</velocity>
        </limit>
        <dynamics>
          <damping>0.01</damping>
          <friction>0</friction>
          <spring_reference>0</spring_reference>
          <spring_stiffness>0</spring_stiffness>
        </dynamics>
        <use_parent_model_frame>1</use_parent_model_frame>
      </axis>
    </joint>
    <link name='left_gripper_finger1_knuckle_link'>
      <pose frame=''>1.22393 0.130555 0.730152 3.08956 -1.39126 -1.62279</pose>
      <inertial>
        <pose frame=''>-0.028253 -0.032416 0 0 -0 0</pose>
        <mass>0.021817</mass>
        <inertia>
          <ixx>9.39482e-06</ixx>
          <ixy>-1.3461e-06</ixy>
          <ixz>0</ixz>
          <iyy>4.07539e-06</iyy>
          <iyz>0</iyz>
          <izz>1.14702e-05</izz>
        </inertia>
      </inertial>
      <collision name='left_gripper_finger1_knuckle_link_collision'>
        <pose frame=''>0 0 0 0 -0 0</pose>
        <geometry>
          <mesh>
            <scale>1 1 1</scale>
            <uri>file://movo/meshes/manipulation/kinova_grippers/collision/finger_knuckle.stl</uri>
          </mesh>
        </geometry>
      </collision>
      <collision name='left_gripper_finger1_knuckle_link_fixed_joint_lump__left_gripper_finger1_finger_tip_link_collision_1'>
        <pose frame=''>-0.024598 -0.036051 0 0 -0 0</pose>
        <geometry>
          <mesh>
            <scale>1 1 1</scale>
            <uri>file://movo/meshes/manipulation/kinova_grippers/collision/finger_tip.stl</uri>
          </mesh>
        </geometry>
      </collision>
      <visual name='left_gripper_finger1_knuckle_link_visual'>
        <pose frame=''>0 0 0 0 -0 0</pose>
        <geometry>
          <mesh>
            <scale>1 1 1</scale>
            <uri>file://movo/meshes/manipulation/kinova_grippers/visual/finger_knuckle.dae</uri>
          </mesh>
        </geometry>
      </visual>
      <visual name='left_gripper_finger1_knuckle_link_fixed_joint_lump__left_gripper_finger1_finger_tip_link_visual_1'>
        <pose frame=''>-0.024598 -0.036051 0 0 -0 0</pose>
        <geometry>
          <mesh>
            <scale>1 1 1</scale>
            <uri>file://movo/meshes/manipulation/kinova_grippers/visual/finger_tip.dae</uri>
          </mesh>
        </geometry>
      </visual>
    </link>
    <joint name='left_gripper_finger1_joint' type='revolute'>
      <child>left_gripper_finger1_knuckle_link</child>
      <parent>left_wrist_3_link</parent>
      <axis>
        <xyz>-0.103009 -0.978563 -0.178336</xyz>
        <limit>
          <lower>0</lower>
          <upper>0.986111</upper>
          <effort>3</effort>
          <velocity>1</velocity>
        </limit>
        <dynamics>
          <spring_reference>0</spring_reference>
          <spring_stiffness>0</spring_stiffness>
        </dynamics>
        <use_parent_model_frame>1</use_parent_model_frame>
      </axis>
    </joint>
    <link name='left_gripper_finger2_knuckle_link'>
      <pose frame=''>1.224 0.155639 0.788723 3.14159 1.38609 -1.5708</pose>
      <inertial>
        <pose frame=''>-0.028253 -0.032416 0 0 -0 0</pose>
        <mass>0.021817</mass>
        <inertia>
          <ixx>9.39482e-06</ixx>
          <ixy>-1.3461e-06</ixy>
          <ixz>0</ixz>
          <iyy>4.07539e-06</iyy>
          <iyz>0</iyz>
          <izz>1.14702e-05</izz>
        </inertia>
      </inertial>
      <collision name='left_gripper_finger2_knuckle_link_collision'>
        <pose frame=''>0 0 0 0 -0 0</pose>
        <geometry>
          <mesh>
            <scale>1 1 1</scale>
            <uri>file://movo/meshes/manipulation/kinova_grippers/collision/finger_knuckle.stl</uri>
          </mesh>
        </geometry>
      </collision>
      <collision name='left_gripper_finger2_knuckle_link_fixed_joint_lump__left_gripper_finger2_finger_tip_link_collision_1'>
        <pose frame=''>-0.024598 -0.036051 0 0 -0 0</pose>
        <geometry>
          <mesh>
            <scale>1 1 1</scale>
            <uri>file://movo/meshes/manipulation/kinova_grippers/collision/finger_tip.stl</uri>
          </mesh>
        </geometry>
      </collision>
      <visual name='left_gripper_finger2_knuckle_link_visual'>
        <pose frame=''>0 0 0 0 -0 0</pose>
        <geometry>
          <mesh>
            <scale>1 1 1</scale>
            <uri>file://movo/meshes/manipulation/kinova_grippers/visual/finger_knuckle.dae</uri>
          </mesh>
        </geometry>
      </visual>
      <visual name='left_gripper_finger2_knuckle_link_fixed_joint_lump__left_gripper_finger2_finger_tip_link_visual_1'>
        <pose frame=''>-0.024598 -0.036051 0 0 -0 0</pose>
        <geometry>
          <mesh>
            <scale>1 1 1</scale>
            <uri>file://movo/meshes/manipulation/kinova_grippers/visual/finger_tip.dae</uri>
          </mesh>
        </geometry>
      </visual>
    </link>
    <joint name='left_gripper_finger2_joint' type='revolute'>
      <child>left_gripper_finger2_knuckle_link</child>
      <parent>left_wrist_3_link</parent>
      <axis>
        <xyz>-0 0.982991 -0.183655</xyz>
        <limit>
          <lower>0</lower>
          <upper>0.986111</upper>
          <effort>3</effort>
          <velocity>1</velocity>
        </limit>
        <dynamics>
          <spring_reference>0</spring_reference>
          <spring_stiffness>0</spring_stiffness>
        </dynamics>
        <use_parent_model_frame>1</use_parent_model_frame>
      </axis>
    </joint>
    <link name='left_gripper_finger3_knuckle_link'>
      <pose frame=''>1.22402 0.111066 0.788693 0 1.3861 1.5708</pose>
      <inertial>
        <pose frame=''>-0.028253 -0.032416 0 0 -0 0</pose>
        <mass>0.021817</mass>
        <inertia>
          <ixx>9.39482e-06</ixx>
          <ixy>-1.3461e-06</ixy>
          <ixz>0</ixz>
          <iyy>4.07539e-06</iyy>
          <iyz>0</iyz>
          <izz>1.14702e-05</izz>
        </inertia>
      </inertial>
      <collision name='left_gripper_finger3_knuckle_link_collision'>
        <pose frame=''>0 0 0 0 -0 0</pose>
        <geometry>
          <mesh>
            <scale>1 1 1</scale>
            <uri>file://movo/meshes/manipulation/kinova_grippers/collision/finger_knuckle.stl</uri>
          </mesh>
        </geometry>
      </collision>
      <collision name='left_gripper_finger3_knuckle_link_fixed_joint_lump__left_gripper_finger3_finger_tip_link_collision_1'>
        <pose frame=''>-0.024598 -0.036051 0 0 -0 0</pose>
        <geometry>
          <mesh>
            <scale>1 1 1</scale>
            <uri>file://movo/meshes/manipulation/kinova_grippers/collision/finger_tip.stl</uri>
          </mesh>
        </geometry>
      </collision>
      <visual name='left_gripper_finger3_knuckle_link_visual'>
        <pose frame=''>0 0 0 0 -0 0</pose>
        <geometry>
          <mesh>
            <scale>1 1 1</scale>
            <uri>file://movo/meshes/manipulation/kinova_grippers/visual/finger_knuckle.dae</uri>
          </mesh>
        </geometry>
      </visual>
      <visual name='left_gripper_finger3_knuckle_link_fixed_joint_lump__left_gripper_finger3_finger_tip_link_visual_1'>
        <pose frame=''>-0.024598 -0.036051 0 0 -0 0</pose>
        <geometry>
          <mesh>
            <scale>1 1 1</scale>
            <uri>file://movo/meshes/manipulation/kinova_grippers/visual/finger_tip.dae</uri>
          </mesh>
        </geometry>
      </visual>
    </link>
    <joint name='left_gripper_finger3_joint' type='revolute'>
      <child>left_gripper_finger3_knuckle_link</child>
      <parent>left_wrist_3_link</parent>
      <axis>
        <xyz>-0 0.982992 0.183648</xyz>
        <limit>
          <lower>0</lower>
          <upper>0.986111</upper>
          <effort>3</effort>
          <velocity>1</velocity>
        </limit>
        <dynamics>
          <spring_reference>0</spring_reference>
          <spring_stiffness>0</spring_stiffness>
        </dynamics>
        <use_parent_model_frame>1</use_parent_model_frame>
      </axis>
    </joint>
    <link name='pan_link'>
      <pose frame=''>0.27449 0 0.870315 3.14159 -0 0</pose>
      <inertial>
        <pose frame=''>-3.6e-05 0.021015 -0.052191 0 -0 0</pose>
        <mass>0.470548</mass>
        <inertia>
          <ixx>0.000957</ixx>
          <ixy>0</ixy>
          <ixz>0</ixz>
          <iyy>0.000805</iyy>
          <iyz>-0.000328</iyz>
          <izz>0.000353</izz>
        </inertia>
      </inertial>
      <collision name='pan_link_collision'>
        <pose frame=''>0 0 0 0 -0 0</pose>
        <geometry>
          <mesh>
            <scale>1 1 1</scale>
            <uri>file://movo/meshes/pan_tilt/collision/pan_link.stl</uri>
          </mesh>
        </geometry>
      </collision>
      <visual name='pan_link_visual'>
        <pose frame=''>0 0 0 0 -0 0</pose>
        <geometry>
          <mesh>
            <scale>1 1 1</scale>
            <uri>file://movo/meshes/pan_tilt/visual/pan_link.dae</uri>
          </mesh>
        </geometry>
      </visual>
    </link>
    <joint name='pan_joint' type='revolute'>
      <child>pan_link</child>
      <parent>linear_actuator_link</parent>
      <axis>
        <xyz>0 -3e-06 -1</xyz>
        <limit>
          <lower>-1.5708</lower>
          <upper>1.5708</upper>
          <effort>7</effort>
          <velocity>0.907571</velocity>
        </limit>
        <dynamics>
          <spring_reference>0</spring_reference>
          <spring_stiffness>0</spring_stiffness>
        </dynamics>
        <use_parent_model_frame>1</use_parent_model_frame>
      </axis>
    </joint>
    <link name='tilt_link'>
      <pose frame=''>0.27449 -0.026 0.961065 0.463649 -1.57079 1.10715</pose>
      <inertial>
        <pose frame=''>0.013478 -0.00669 -0.040467 0 -0 0</pose>
        <mass>1.83451</mass>
        <inertia>
          <ixx>0.00777963</ixx>
          <ixy>-5.63296e-05</ixy>
          <ixz>-0.000358143</ixz>
          <iyy>0.00239627</iyy>
          <iyz>-0.00019448</iyz>
          <izz>0.00257745</izz>
        </inertia>
      </inertial>
      <collision name='tilt_link_collision'>
        <pose frame=''>0 0 0 0 -0 0</pose>
        <geometry>
          <mesh>
            <scale>1 1 1</scale>
            <uri>file://movo/meshes/pan_tilt/collision/tilt_link.stl</uri>
          </mesh>
        </geometry>
      </collision>
      <collision name='tilt_link_fixed_joint_lump__movo_camera_link_collision_1'>
        <pose frame=''>0.05825 -0.010588 -0.026 -1.57079 -0 -1.57079</pose>
        <geometry>
          <mesh>
            <scale>1 1 1</scale>
            <uri>file://movo/meshes/sensors/collision/kinect_one_collision.stl</uri>
          </mesh>
        </geometry>
      </collision>
      <visual name='tilt_link_visual'>
        <pose frame=''>0 0 0 0 -0 0</pose>
        <geometry>
          <mesh>
            <scale>1 1 1</scale>
            <uri>file://movo/meshes/pan_tilt/visual/tilt_link.dae</uri>
          </mesh>
        </geometry>
      </visual>
      <visual name='tilt_link_fixed_joint_lump__movo_camera_link_visual_1'>
        <pose frame=''>0.05825 -0.010588 -0.026 -1.57079 -0 -1.57079</pose>
        <geometry>
          <mesh>
            <scale>1 1 1</scale>
            <uri>file://movo/meshes/sensors/visual/kinect_one.dae</uri>
          </mesh>
        </geometry>
      </visual>
    </link>
    <joint name='tilt_joint' type='revolute'>
      <child>tilt_link</child>
      <parent>pan_link</parent>
      <axis>
        <xyz>1e-06 -1 3e-06</xyz>
        <limit>
          <lower>-1.5708</lower>
          <upper>1.5708</upper>
          <effort>7</effort>
          <velocity>0.907571</velocity>
        </limit>
        <dynamics>
          <spring_reference>0</spring_reference>
          <spring_stiffness>0</spring_stiffness>
        </dynamics>
        <use_parent_model_frame>1</use_parent_model_frame>
      </axis>
    </joint>
    <link name='right_shoulder_link'>
      <pose frame=''>0.165745 -0.13335 0.75007 -1.5708 0 1.5708</pose>
      <inertial>
        <pose frame=''>1.8e-05 -0.004667 -0.060609 0 -0 0</pose>
        <mass>0.824524</mass>
        <inertia>
          <ixx>0.002561</ixx>
          <ixy>0</ixy>
          <ixz>1e-06</ixz>
          <iyy>0.002653</iyy>
          <iyz>0.000212</iyz>
          <izz>0.000524</izz>
        </inertia>
      </inertial>
      <collision name='right_shoulder_link_collision'>
        <pose frame=''>0 0 0 0 -0 0</pose>
        <geometry>
          <mesh>
            <scale>1 1 1</scale>
            <uri>file://movo/meshes/manipulation/jaco/collision/shoulder_7dof.stl</uri>
          </mesh>
        </geometry>
      </collision>
      <visual name='right_shoulder_link_visual'>
        <pose frame=''>0 0 0 0 -0 0</pose>
        <geometry>
          <mesh>
            <scale>1 1 1</scale>
            <uri>file://movo/meshes/manipulation/jaco/visual/shoulder_7dof.dae</uri>
          </mesh>
        </geometry>
      </visual>
    </link>
    <joint name='right_shoulder_pan_joint' type='revolute'>
      <child>right_shoulder_link</child>
      <parent>linear_actuator_link</parent>
      <axis>
        <xyz>-1 -0 -0</xyz>
        <limit>
          <lower>-3.14159</lower>
          <upper>3.14159</upper>
          <effort>18000</effort>
          <velocity>0.69115</velocity>
        </limit>
        <dynamics>
          <damping>0.01</damping>
          <friction>0</friction>
          <spring_reference>0</spring_reference>
          <spring_stiffness>0</spring_stiffness>
        </dynamics>
        <use_parent_model_frame>1</use_parent_model_frame>
      </axis>
    </joint>
    <link name='right_arm_half_1_link'>
      <pose frame=''>0.284495 -0.13335 0.75007 -0 0 1.5708</pose>
      <inertial>
        <pose frame=''>0 -0.103563 0 0 -0 0</pose>
        <mass>0.8447</mass>
        <inertia>
          <ixx>0.000435</ixx>
          <ixy>2e-06</ixy>
          <ixz>0.000231</ixz>
          <iyy>0.034947</iyy>
          <iyz>0</iyz>
          <izz>0.035198</izz>
        </inertia>
      </inertial>
      <collision name='right_arm_half_1_link_collision'>
        <pose frame=''>0 0 0 0 -0 0</pose>
        <geometry>
          <mesh>
            <scale>1 1 1</scale>
            <uri>file://movo/meshes/manipulation/jaco/collision/arm_half_1.stl</uri>
          </mesh>
        </geometry>
      </collision>
      <visual name='right_arm_half_1_link_visual'>
        <pose frame=''>0 0 0 0 -0 0</pose>
        <geometry>
          <mesh>
            <scale>1 1 1</scale>
            <uri>file://movo/meshes/manipulation/jaco/visual/arm_half_1.dae</uri>
          </mesh>
        </geometry>
      </visual>
    </link>
    <joint name='right_shoulder_lift_joint' type='revolute'>
      <child>right_arm_half_1_link</child>
      <parent>right_shoulder_link</parent>
      <axis>
        <xyz>-0 0 1</xyz>
        <limit>
          <lower>-2.238</lower>
          <upper>2.238</upper>
          <effort>30000.5</effort>
          <velocity>0.69115</velocity>
        </limit>
        <dynamics>
          <damping>0.01</damping>
          <friction>0</friction>
          <spring_reference>0</spring_reference>
          <spring_stiffness>0</spring_stiffness>
        </dynamics>
        <use_parent_model_frame>1</use_parent_model_frame>
      </axis>
    </joint>
    <link name='right_arm_half_2_link'>
      <pose frame=''>0.489495 -0.13335 0.75007 -1.5708 0 1.5708</pose>
      <inertial>
        <pose frame=''>0 0 -0.102245 0 -0 0</pose>
        <mass>0.8447</mass>
        <inertia>
          <ixx>0.000435</ixx>
          <ixy>2e-06</ixy>
          <ixz>0.000231</ixz>
          <iyy>0.034947</iyy>
          <iyz>0</iyz>
          <izz>0.035198</izz>
        </inertia>
      </inertial>
      <collision name='right_arm_half_2_link_collision'>
        <pose frame=''>0 0 0 0 -0 0</pose>
        <geometry>
          <mesh>
            <scale>1 1 1</scale>
            <uri>file://movo/meshes/manipulation/jaco/collision/arm_half_2.stl</uri>
          </mesh>
        </geometry>
      </collision>
      <visual name='right_arm_half_2_link_visual'>
        <pose frame=''>0 0 0 0 -0 0</pose>
        <geometry>
          <mesh>
            <scale>1 1 1</scale>
            <uri>file://movo/meshes/manipulation/jaco/visual/arm_half_2.dae</uri>
          </mesh>
        </geometry>
      </visual>
    </link>
    <joint name='right_arm_half_joint' type='revolute'>
      <child>right_arm_half_2_link</child>
      <parent>right_arm_half_1_link</parent>
      <axis>
        <xyz>-1 -0 -0</xyz>
        <limit>
          <lower>-3.14159</lower>
          <upper>3.14159</upper>
          <effort>30000.5</effort>
          <velocity>0.69115</velocity>
        </limit>
        <dynamics>
          <damping>0.01</damping>
          <friction>0</friction>
          <spring_reference>0</spring_reference>
          <spring_stiffness>0</spring_stiffness>
        </dynamics>
        <use_parent_model_frame>1</use_parent_model_frame>
      </axis>
    </joint>
    <link name='right_forearm_link'>
      <pose frame=''>0.694495 -0.13335 0.75007 -3.14159 0 1.5708</pose>
      <inertial>
        <pose frame=''>0 0.081 -0.0086 0 -0 0</pose>
        <mass>0.674254</mass>
        <inertia>
          <ixx>0.005453</ixx>
          <ixy>3e-06</ixy>
          <ixz>0</ixz>
          <iyy>0.000305</iyy>
          <iyz>8.7e-05</iyz>
          <izz>0.005578</izz>
        </inertia>
      </inertial>
      <collision name='right_forearm_link_collision'>
        <pose frame=''>0 0 0 0 -0 0</pose>
        <geometry>
          <mesh>
            <scale>1 1 1</scale>
            <uri>file://movo/meshes/manipulation/jaco/collision/forearm_7dof.stl</uri>
          </mesh>
        </geometry>
      </collision>
      <visual name='right_forearm_link_visual'>
        <pose frame=''>0 0 0 0 -0 0</pose>
        <geometry>
          <mesh>
            <scale>1 1 1</scale>
            <uri>file://movo/meshes/manipulation/jaco/visual/forearm_7dof.dae</uri>
          </mesh>
        </geometry>
      </visual>
    </link>
    <joint name='right_elbow_joint' type='revolute'>
      <child>right_forearm_link</child>
      <parent>right_arm_half_2_link</parent>
      <axis>
        <xyz>-0 -0 -1</xyz>
        <limit>
          <lower>-2.809</lower>
          <upper>2.809</upper>
          <effort>18000</effort>
          <velocity>0.69115</velocity>
        </limit>
        <dynamics>
          <damping>0.01</damping>
          <friction>0</friction>
          <spring_reference>0</spring_reference>
          <spring_stiffness>0</spring_stiffness>
        </dynamics>
        <use_parent_model_frame>1</use_parent_model_frame>
      </axis>
    </joint>
    <link name='right_wrist_spherical_1_link'>
      <pose frame=''>0.901795 -0.13335 0.76147 1.5708 -0 -1.5708</pose>
      <inertial>
        <pose frame=''>0 0.002885 -0.054193 0 -0 0</pose>
        <mass>0.463</mass>
        <inertia>
          <ixx>0.000392</ixx>
          <ixy>0</ixy>
          <ixz>0</ixz>
          <iyy>0.000347</iyy>
          <iyz>0.000101</iyz>
          <izz>0.000233</izz>
        </inertia>
      </inertial>
      <collision name='right_wrist_spherical_1_link_collision'>
        <pose frame=''>0 0 0 0 -0 0</pose>
        <geometry>
          <mesh>
            <scale>1 1 1</scale>
            <uri>file://movo/meshes/manipulation/jaco/collision/wrist_spherical_1.stl</uri>
          </mesh>
        </geometry>
      </collision>
      <visual name='right_wrist_spherical_1_link_visual'>
        <pose frame=''>0 0 0 0 -0 0</pose>
        <geometry>
          <mesh>
            <scale>1 1 1</scale>
            <uri>file://movo/meshes/manipulation/jaco/visual/wrist_spherical_1.dae</uri>
          </mesh>
        </geometry>
      </visual>
    </link>
    <joint name='right_wrist_spherical_1_joint' type='revolute'>
      <child>right_wrist_spherical_1_link</child>
      <parent>right_forearm_link</parent>
      <axis>
        <xyz>-1 -0 0</xyz>
        <limit>
          <lower>-3.14159</lower>
          <upper>3.14159</upper>
          <effort>60000.8</effort>
          <velocity>0.921534</velocity>
        </limit>
        <dynamics>
          <damping>0.01</damping>
          <friction>0</friction>
          <spring_reference>0</spring_reference>
          <spring_stiffness>0</spring_stiffness>
        </dynamics>
        <use_parent_model_frame>1</use_parent_model_frame>
      </axis>
    </joint>
    <link name='right_wrist_spherical_2_link'>
      <pose frame=''>1.00554 -0.13335 0.76147 -0 -0 -1.5708</pose>
      <inertial>
        <pose frame=''>0 0.049721 -0.002856 0 -0 0</pose>
        <mass>0.463</mass>
        <inertia>
          <ixx>0.000392</ixx>
          <ixy>0</ixy>
          <ixz>0</ixz>
          <iyy>0.000347</iyy>
          <iyz>0.000101</iyz>
          <izz>0.000233</izz>
        </inertia>
      </inertial>
      <collision name='right_wrist_spherical_2_link_collision'>
        <pose frame=''>0 0 0 0 -0 0</pose>
        <geometry>
          <mesh>
            <scale>1 1 1</scale>
            <uri>file://movo/meshes/manipulation/jaco/collision/wrist_spherical_2.stl</uri>
          </mesh>
        </geometry>
      </collision>
      <visual name='right_wrist_spherical_2_link_visual'>
        <pose frame=''>0 0 0 0 -0 0</pose>
        <geometry>
          <mesh>
            <scale>1 1 1</scale>
            <uri>file://movo/meshes/manipulation/jaco/visual/wrist_spherical_2.dae</uri>
          </mesh>
        </geometry>
      </visual>
    </link>
    <joint name='right_wrist_spherical_2_joint' type='revolute'>
      <child>right_wrist_spherical_2_link</child>
      <parent>right_wrist_spherical_1_link</parent>
      <axis>
        <xyz>0 0 1</xyz>
        <limit>
          <lower>-2.78</lower>
          <upper>2.78</upper>
          <effort>60000.8</effort>
          <velocity>0.921534</velocity>
        </limit>
        <dynamics>
          <damping>0.01</damping>
          <friction>0</friction>
          <spring_reference>0</spring_reference>
          <spring_stiffness>0</spring_stiffness>
        </dynamics>
        <use_parent_model_frame>1</use_parent_model_frame>
      </axis>
    </joint>
    <link name='right_wrist_3_link'>
      <pose frame=''>1.10929 -0.13335 0.76147 -1.5708 0 1.5708</pose>
      <inertial>
        <pose frame=''>-0.000152 -0.004169 -0.09596 0 -0 0</pose>
        <mass>0.990094</mass>
        <inertia>
          <ixx>0.00425431</ixx>
          <ixy>6.65278e-07</ixy>
          <ixz>-1.49586e-05</ixz>
          <iyy>0.00411121</iyy>
          <iyz>0.000122735</iyz>
          <izz>0.000899307</izz>
        </inertia>
      </inertial>
      <collision name='right_wrist_3_link_collision'>
        <pose frame=''>0 0 0 0 -0 0</pose>
        <geometry>
          <mesh>
            <scale>1 1 1</scale>
            <uri>file://movo/meshes/manipulation/jaco/collision/kinova_actuator_gearing.stl</uri>
          </mesh>
        </geometry>
      </collision>
      <collision name='right_wrist_3_link_fixed_joint_lump__right_gripper_base_link_collision_1'>
        <pose frame=''>-0 0 0 0 -0 0</pose>
        <geometry>
          <mesh>
            <scale>1 1 1</scale>
            <uri>file://movo/meshes/manipulation/kinova_grippers/collision/kg3_base_link.stl</uri>
          </mesh>
        </geometry>
      </collision>
      <visual name='right_wrist_3_link_visual'>
        <pose frame=''>0 0 0 0 -0 0</pose>
        <geometry>
          <mesh>
            <scale>1 1 1</scale>
            <uri>file://movo/meshes/manipulation/jaco/visual/kinova_actuator_gearing.dae</uri>
          </mesh>
        </geometry>
      </visual>
      <visual name='right_wrist_3_link_fixed_joint_lump__right_gripper_base_link_visual_1'>
        <pose frame=''>-0 0 0 0 -0 0</pose>
        <geometry>
          <mesh>
            <scale>1 1 1</scale>
            <uri>file://movo/meshes/manipulation/kinova_grippers/visual/kg3_base_link.dae</uri>
          </mesh>
        </geometry>
      </visual>
    </link>
    <joint name='right_wrist_3_joint' type='revolute'>
      <child>right_wrist_3_link</child>
      <parent>right_wrist_spherical_2_link</parent>
      <axis>
        <xyz>-1 -0 -0</xyz>
        <limit>
          <lower>-3.14159</lower>
          <upper>3.14159</upper>
          <effort>60000.8</effort>
          <velocity>0.921534</velocity>
        </limit>
        <dynamics>
          <damping>0.01</damping>
          <friction>0</friction>
          <spring_reference>0</spring_reference>
          <spring_stiffness>0</spring_stiffness>
        </dynamics>
        <use_parent_model_frame>1</use_parent_model_frame>
      </axis>
    </joint>   
    <link name='right_gripper_finger1_knuckle_link'>
      <pose frame=''>1.22393 -0.136145 0.730152 3.08956 -1.39126 -1.62279</pose>
      <inertial>
        <pose frame=''>-0.028253 -0.032416 0 0 -0 0</pose>
        <mass>0.021817</mass>
        <inertia>
          <ixx>9.39482e-06</ixx>
          <ixy>-1.3461e-06</ixy>
          <ixz>0</ixz>
          <iyy>4.07539e-06</iyy>
          <iyz>0</iyz>
          <izz>1.14702e-05</izz>
        </inertia>
      </inertial>
      <collision name='right_gripper_finger1_knuckle_link_collision'>
        <pose frame=''>0 0 0 0 -0 0</pose>
        <geometry>
          <mesh>
            <scale>1 1 1</scale>
            <uri>file://movo/meshes/manipulation/kinova_grippers/collision/finger_knuckle.stl</uri>
          </mesh>
        </geometry>
      </collision>
      <collision name='right_gripper_finger1_knuckle_link_fixed_joint_lump__right_gripper_finger1_finger_tip_link_collision_1'>
        <pose frame=''>-0.024598 -0.036051 0 0 -0 0</pose>
        <geometry>
          <mesh>
            <scale>1 1 1</scale>
            <uri>file://movo/meshes/manipulation/kinova_grippers/collision/finger_tip.stl</uri>
          </mesh>
        </geometry>
      </collision>
      <visual name='right_gripper_finger1_knuckle_link_visual'>
        <pose frame=''>0 0 0 0 -0 0</pose>
        <geometry>
          <mesh>
            <scale>1 1 1</scale>
            <uri>file://movo/meshes/manipulation/kinova_grippers/visual/finger_knuckle.dae</uri>
          </mesh>
        </geometry>
      </visual>
      <visual name='right_gripper_finger1_knuckle_link_fixed_joint_lump__right_gripper_finger1_finger_tip_link_visual_1'>
        <pose frame=''>-0.024598 -0.036051 0 0 -0 0</pose>
        <geometry>
          <mesh>
            <scale>1 1 1</scale>
            <uri>file://movo/meshes/manipulation/kinova_grippers/visual/finger_tip.dae</uri>
          </mesh>
        </geometry>
      </visual>
    </link>
    <joint name='right_gripper_finger1_joint' type='revolute'>
      <child>right_gripper_finger1_knuckle_link</child>
      <parent>right_wrist_3_link</parent>
      <axis>
        <xyz>-0.103009 -0.978563 -0.178336</xyz>
        <limit>
          <lower>0</lower>
          <upper>0.986111</upper>
          <effort>3</effort>
          <velocity>1</velocity>
        </limit>
        <dynamics>
          <spring_reference>0</spring_reference>
          <spring_stiffness>0</spring_stiffness>
        </dynamics>
        <use_parent_model_frame>1</use_parent_model_frame>
      </axis>
    </joint>
    <link name='right_gripper_finger2_knuckle_link'>
      <pose frame=''>1.224 -0.111061 0.788723 3.14159 1.38609 -1.5708</pose>
      <inertial>
        <pose frame=''>-0.028253 -0.032416 0 0 -0 0</pose>
        <mass>0.021817</mass>
        <inertia>
          <ixx>9.39482e-06</ixx>
          <ixy>-1.3461e-06</ixy>
          <ixz>0</ixz>
          <iyy>4.07539e-06</iyy>
          <iyz>0</iyz>
          <izz>1.14702e-05</izz>
        </inertia>
      </inertial>
      <collision name='right_gripper_finger2_knuckle_link_collision'>
        <pose frame=''>0 0 0 0 -0 0</pose>
        <geometry>
          <mesh>
            <scale>1 1 1</scale>
            <uri>file://movo/meshes/manipulation/kinova_grippers/collision/finger_knuckle.stl</uri>
          </mesh>
        </geometry>
      </collision>
      <collision name='right_gripper_finger2_knuckle_link_fixed_joint_lump__right_gripper_finger2_finger_tip_link_collision_1'>
        <pose frame=''>-0.024598 -0.036051 0 0 -0 0</pose>
        <geometry>
          <mesh>
            <scale>1 1 1</scale>
            <uri>file://movo/meshes/manipulation/kinova_grippers/collision/finger_tip.stl</uri>
          </mesh>
        </geometry>
      </collision>
      <visual name='right_gripper_finger2_knuckle_link_visual'>
        <pose frame=''>0 0 0 0 -0 0</pose>
        <geometry>
          <mesh>
            <scale>1 1 1</scale>
            <uri>file://movo/meshes/manipulation/kinova_grippers/visual/finger_knuckle.dae</uri>
          </mesh>
        </geometry>
      </visual>
      <visual name='right_gripper_finger2_knuckle_link_fixed_joint_lump__right_gripper_finger2_finger_tip_link_visual_1'>
        <pose frame=''>-0.024598 -0.036051 0 0 -0 0</pose>
        <geometry>
          <mesh>
            <scale>1 1 1</scale>
            <uri>file://movo/meshes/manipulation/kinova_grippers/visual/finger_tip.dae</uri>
          </mesh>
        </geometry>
      </visual>
    </link>
    <joint name='right_gripper_finger2_joint' type='revolute'>
      <child>right_gripper_finger2_knuckle_link</child>
      <parent>right_wrist_3_link</parent>
      <axis>
        <xyz>-0 0.982991 -0.183655</xyz>
        <limit>
          <lower>0</lower>
          <upper>0.986111</upper>
          <effort>3</effort>
          <velocity>1</velocity>
        </limit>
        <dynamics>
          <spring_reference>0</spring_reference>
          <spring_stiffness>0</spring_stiffness>
        </dynamics>
        <use_parent_model_frame>1</use_parent_model_frame>
      </axis>
    </joint>
    <link name='right_gripper_finger3_knuckle_link'>
      <pose frame=''>1.22402 -0.155634 0.788693 0 1.3861 1.5708</pose>
      <inertial>
        <pose frame=''>-0.028253 -0.032416 0 0 -0 0</pose>
        <mass>0.021817</mass>
        <inertia>
          <ixx>9.39482e-06</ixx>
          <ixy>-1.3461e-06</ixy>
          <ixz>0</ixz>
          <iyy>4.07539e-06</iyy>
          <iyz>0</iyz>
          <izz>1.14702e-05</izz>
        </inertia>
      </inertial>
      <collision name='right_gripper_finger3_knuckle_link_collision'>
        <pose frame=''>0 0 0 0 -0 0</pose>
        <geometry>
          <mesh>
            <scale>1 1 1</scale>
            <uri>file://movo/meshes/manipulation/kinova_grippers/collision/finger_knuckle.stl</uri>
          </mesh>
        </geometry>
      </collision>
      <collision name='right_gripper_finger3_knuckle_link_fixed_joint_lump__right_gripper_finger3_finger_tip_link_collision_1'>
        <pose frame=''>-0.024598 -0.036051 0 0 -0 0</pose>
        <geometry>
          <mesh>
            <scale>1 1 1</scale>
            <uri>file://movo/meshes/manipulation/kinova_grippers/collision/finger_tip.stl</uri>
          </mesh>
        </geometry>
      </collision>
      <visual name='right_gripper_finger3_knuckle_link_visual'>
        <pose frame=''>0 0 0 0 -0 0</pose>
        <geometry>
          <mesh>
            <scale>1 1 1</scale>
            <uri>file://movo/meshes/manipulation/kinova_grippers/visual/finger_knuckle.dae</uri>
          </mesh>
        </geometry>
      </visual>
      <visual name='right_gripper_finger3_knuckle_link_fixed_joint_lump__right_gripper_finger3_finger_tip_link_visual_1'>
        <pose frame=''>-0.024598 -0.036051 0 0 -0 0</pose>
        <geometry>
          <mesh>
            <scale>1 1 1</scale>
            <uri>file://movo/meshes/manipulation/kinova_grippers/visual/finger_tip.dae</uri>
          </mesh>
        </geometry>
      </visual>
    </link>
    <joint name='right_gripper_finger3_joint' type='revolute'>
      <child>right_gripper_finger3_knuckle_link</child>
      <parent>right_wrist_3_link</parent>
      <axis>
        <xyz>-0 0.982992 0.183648</xyz>
        <limit>
          <lower>0</lower>
          <upper>0.986111</upper>
          <effort>3</effort>
          <velocity>1</velocity>
        </limit>
        <dynamics>
          <spring_reference>0</spring_reference>
          <spring_stiffness>0</spring_stiffness>
        </dynamics>
        <use_parent_model_frame>1</use_parent_model_frame>
      </axis>
    </joint>
    <link name='mid_body_link'>
      <pose frame=''>0.07714 0 0.470076 0 -0 0</pose>
      <inertial>
        <pose frame=''>-0.07714 0 0.026602 0 -0 0</pose>
        <mass>2.24684</mass>
        <inertia>
          <ixx>0.067276</ixx>
          <ixy>0</ixy>
          <ixz>0</ixz>
          <iyy>0.073946</iyy>
          <iyz>0</iyz>
          <izz>0.102656</izz>
        </inertia>
      </inertial>
      <visual name='mid_body_link_visual'>
        <pose frame=''>0 0 0 0 -0 0</pose>
        <geometry>
          <mesh>
            <scale>1 1 1</scale>
            <uri>file://movo/meshes/movo_body/movo_mid_body.dae</uri>
          </mesh>
        </geometry>
      </visual>
    </link>
    <joint name='mid_body_joint' type='prismatic'>
      <child>mid_body_link</child>
      <parent>base_link</parent>
      <axis>
        <xyz>0 0 1</xyz>
        <limit>
          <lower>0</lower>
          <upper>0.254561</upper>
          <effort>1000</effort>
          <velocity>0.2</velocity>
        </limit>
        <dynamics>
          <damping>0</damping>
          <friction>0</friction>
          <spring_reference>0</spring_reference>
          <spring_stiffness>0</spring_stiffness>
        </dynamics>
        <use_parent_model_frame>1</use_parent_model_frame>
      </axis>
    </joint>
    <link name='left_ee_link'>
      <pose frame=''>1.214290 0.13335 0.76147 1.5708 -0 0</pose>
      <inertial>
        <pose frame=''>-0.09272 0.005175 -7e-06 0 -0 0</pose>
        <mass>0.799312</mass>
        <inertia>
          <ixx>0.000823</ixx>
          <ixy>3e-06</ixy>
          <ixz>4e-06</ixz>
          <iyy>0.00065</iyy>
          <iyz>-1.43592e-14</iyz>
          <izz>0.00079</izz>
        </inertia>
      </inertial>      
      <collision name="left_ee_link_collision">
        <pose frame=''>0 0 0 0 0 0</pose>
        <geometry>
          <sphere>
            <radius>0.01</radius>
          </sphere>
        </geometry>
      </collision>
      <visual name='left_ee_link_visual'>
        <pose frame=''>0 0 0 0 -0 0</pose>
        <geometry>
          <sphere>
            <radius>0.01</radius>
          </sphere>
        </geometry>
        <material>
          <ambient>0.7 0.7 0.7 1.0</ambient>          
        </material>
      </visual>        
      <gravity>0</gravity>
      <velocity_decay/>
    </link>
    <joint name='left_ee_fixed_joint' type='fixed'>
      <child>left_ee_link</child>
      <parent>left_wrist_3_link</parent>      
    </joint>
    <link name='right_ee_link'>
      <pose frame=''>1.214290 -0.133350 0.76147 1.5708 -0 0</pose>
      <inertial>
        <pose frame=''>-0.09272 0.005175 -7e-06 0 -0 0</pose>
        <mass>0.799312</mass>
        <inertia>
          <ixx>0.000823</ixx>
          <ixy>3e-06</ixy>
          <ixz>4e-06</ixz>
          <iyy>0.00065</iyy>
          <iyz>-1.43592e-14</iyz>
          <izz>0.00079</izz>
        </inertia>
      </inertial>      
      <collision name="right_ee_link_collision">
        <pose frame=''>0 0 0 0 0 0</pose>
        <geometry>
          <sphere>
            <radius>0.01</radius>
          </sphere>
        </geometry>
      </collision>
      <visual name='right_ee_link_visual'>
        <pose frame=''>0 0 0 0 -0 0</pose>
        <geometry>
          <sphere>
            <radius>0.01</radius>
          </sphere>
        </geometry>
        <material>
          <ambient>0.7 0.7 0.7 1.0</ambient>          
        </material>
      </visual>      
      <gravity>0</gravity>
      <velocity_decay/>
    </link>
    <joint name='right_ee_fixed_joint' type='fixed'>
      <child>right_ee_link</child>
      <parent>right_wrist_3_link</parent>      
    </joint>    
  </model>
</sdf>
